<mujoco model="planar walker">
  <include file="./common/visual.xml"/>
  <include file="./common/skybox.xml"/>
  <include file="./common/materials.xml"/>

  <option timestep="0.0025"/>

  <statistic extent="2" center="0 0 1"/>

  <default>
    <joint damping=".1" armature="0.01" limited="true" solimplimit="0 .99 .01"/>
    <geom contype="1" conaffinity="0" friction=".7 .1 .1"/>
    <motor ctrlrange="-1 1" ctrllimited="true"/>
    <site size="0.01"/>
    <default class="walker">
      <geom material="self" type="capsule"/>
      <joint axis="0 -1 0"/>
    </default>
  </default>
<!-- 
  <worldbody>
    <geom name='box' type='box' size='0.65 0.65 0.65' pos='1 0 0.67'/>
  </worldbody>
-->
  <worldbody>
    <geom name="floor" type="plane" conaffinity="1" pos="248 0 0" size="250 .8 .2" material="grid" zaxis="0 0 1"/>
    <body name="torso" pos="0 0 1.16" childclass="walker">
      <light name="light" pos="0 0 2" mode="trackcom"/>
      <camera name="side" pos="0 -2 .7" euler="60 0 0" mode="trackcom"/>
      <camera name="back" pos="-2 0 .5" xyaxes="0 -1 0 1 0 3" mode="trackcom"/>
      <joint name="rootz" axis="0 0 1" type="slide" limited="false" armature="0" damping="0"/>
      <joint name="rootx" axis="1 0 0" type="slide" limited="false" armature="0" damping="0"/>
      <joint name="rooty" axis="0 1 0" type="hinge" limited="false" armature="0" damping="0"/>
      <geom name="torso" type='box' size='0.15 0.2 0.15'/>
      <body name="right_thigh" pos="0 -.1 -0.15">
        <joint name="right_knee_X" range="-0 80" axis='-1 0 0'/>
        <joint name="right_knee" range="-90 90"/>
        <geom name="right_thigh" pos="0 0 -0.225" size="0.05 0.225"/>
        <body name="right_leg" pos="0 0 -0.7">
          <joint name="right_shin" pos="0 0 0.25" range="35 135"/>
          <geom name="right_leg" size="0.04 0.25"/>
        </body>
      </body>
      <body name="left_thigh" pos="0 .1 -0.15" >
        <joint name="left_knee_X" range="-80 0" axis='-1 0 0'/>
        <joint name="left_knee" range="-90 90"/>
        <geom name="left_thigh" pos="0 0 -0.225" size="0.05 0.225"/>
        <body name="left_leg" pos="0 0 -0.7">
          <joint name="left_shin" pos="0 0 0.25" range="35 135"/>
          <geom name="left_leg" size="0.04 0.25"/>
        </body>
      </body>
    </body>
  </worldbody>

  <sensor>
    <subtreelinvel name="torso_subtreelinvel" body="torso"/>
  </sensor>

  <actuator>
    <motor name="left_knee" joint="left_knee" gear="100"/>
    <motor name="left_knee X" joint="left_knee_X" gear="100"/>
    <motor name="right_knee" joint="right_knee" gear="100"/>
    <motor name="right_knee X" joint="right_knee_X" gear="100"/>
    <motor name="left_shin" joint="left_shin" gear="50"/>
    <motor name="right_shin" joint="right_shin" gear="50"/>
  </actuator>
</mujoco>
